Traceback (most recent call last):
  File "<frozen runpy>", line 198, in _run_module_as_main
  File "<frozen runpy>", line 88, in _run_code
  File "/Library/Frameworks/Python.framework/Versions/3.12/lib/python3.12/site-packages/uvicorn/__main__.py", line 4, in <module>
    uvicorn.main()
  File "/Library/Frameworks/Python.framework/Versions/3.12/lib/python3.12/site-packages/click/core.py", line 1157, in __call__
    return self.main(*args, **kwargs)
           ^^^^^^^^^^^^^^^^^^^^^^^^^^
  File "/Library/Frameworks/Python.framework/Versions/3.12/lib/python3.12/site-packages/click/core.py", line 1078, in main
    rv = self.invoke(ctx)
         ^^^^^^^^^^^^^^^^
  File "/Library/Frameworks/Python.framework/Versions/3.12/lib/python3.12/site-packages/click/core.py", line 1434, in invoke
    return ctx.invoke(self.callback, **ctx.params)
           ^^^^^^^^^^^^^^^^^^^^^^^^^^^^^^^^^^^^^^^
  File "/Library/Frameworks/Python.framework/Versions/3.12/lib/python3.12/site-packages/click/core.py", line 783, in invoke
    return __callback(*args, **kwargs)
           ^^^^^^^^^^^^^^^^^^^^^^^^^^^
  File "/Library/Frameworks/Python.framework/Versions/3.12/lib/python3.12/site-packages/uvicorn/main.py", line 409, in main
    run(
  File "/Library/Frameworks/Python.framework/Versions/3.12/lib/python3.12/site-packages/uvicorn/main.py", line 575, in run
    server.run()
  File "/Library/Frameworks/Python.framework/Versions/3.12/lib/python3.12/site-packages/uvicorn/server.py", line 65, in run
    return asyncio.run(self.serve(sockets=sockets))
           ^^^^^^^^^^^^^^^^^^^^^^^^^^^^^^^^^^^^^^^^
  File "/Library/Frameworks/Python.framework/Versions/3.12/lib/python3.12/asyncio/runners.py", line 195, in run
    return runner.run(main)
           ^^^^^^^^^^^^^^^^
  File "/Library/Frameworks/Python.framework/Versions/3.12/lib/python3.12/asyncio/runners.py", line 118, in run
    return self._loop.run_until_complete(task)
           ^^^^^^^^^^^^^^^^^^^^^^^^^^^^^^^^^^^
  File "/Library/Frameworks/Python.framework/Versions/3.12/lib/python3.12/asyncio/base_events.py", line 691, in run_until_complete
    return future.result()
           ^^^^^^^^^^^^^^^
  File "/Library/Frameworks/Python.framework/Versions/3.12/lib/python3.12/site-packages/uvicorn/server.py", line 69, in serve
    await self._serve(sockets)
  File "/Library/Frameworks/Python.framework/Versions/3.12/lib/python3.12/site-packages/uvicorn/server.py", line 76, in _serve
    config.load()
  File "/Library/Frameworks/Python.framework/Versions/3.12/lib/python3.12/site-packages/uvicorn/config.py", line 439, in load
    self.loaded_app = self.loaded_app()
                      ^^^^^^^^^^^^^^^^^
  File "/Users/ryan/src/msec/atgx/azure-tenant-grapher/src/visualization/server.py", line 14, in create_app
    from src.graph_visualizer import GraphVisualizer
  File "/Users/ryan/src/msec/atgx/azure-tenant-grapher/src/graph_visualizer.py", line 14, in <module>
    import colorlog
ModuleNotFoundError: No module named 'colorlog'
[DEBUG] create_app: routers and static mounted.
Failed to connect to Neo4j: Couldn't connect to localhost:7687 (resolved to ('[::1]:7687', '127.0.0.1:7687')):
Failed to establish connection to ResolvedIPv6Address(('::1', 7687, 0, 0)) (reason [Errno 61] Connection refused)
Failed to establish connection to ResolvedIPv4Address(('127.0.0.1', 7687)) (reason [Errno 61] Connection refused)
Traceback (most recent call last):
  File "/Library/Frameworks/Python.framework/Versions/3.12/lib/python3.12/site-packages/neo4j/_async_compat/network/_bolt_socket.py", line 409, in _connect_secure
    s.connect(resolved_address)
ConnectionRefusedError: [Errno 61] Connection refused

The above exception was the direct cause of the following exception:

Traceback (most recent call last):
  File "/Library/Frameworks/Python.framework/Versions/3.12/lib/python3.12/site-packages/neo4j/_sync/io/_bolt_socket.py", line 328, in connect
    s = cls._connect_secure(
        ^^^^^^^^^^^^^^^^^^^^
  File "/Library/Frameworks/Python.framework/Versions/3.12/lib/python3.12/site-packages/neo4j/_async_compat/network/_bolt_socket.py", line 426, in _connect_secure
    raise ServiceUnavailable(
neo4j.exceptions.ServiceUnavailable: Failed to establish connection to ResolvedIPv6Address(('::1', 7687, 0, 0)) (reason [Errno 61] Connection refused)

The above exception was the direct cause of the following exception:

Traceback (most recent call last):
  File "/Users/ryan/src/msec/atgx/azure-tenant-grapher/src/graph_visualizer.py", line 65, in connect
    session.run("RETURN 1")
  File "/Library/Frameworks/Python.framework/Versions/3.12/lib/python3.12/site-packages/neo4j/_sync/work/session.py", line 313, in run
    self._connect(self._config.default_access_mode)
  File "/Library/Frameworks/Python.framework/Versions/3.12/lib/python3.12/site-packages/neo4j/_sync/work/session.py", line 136, in _connect
    super()._connect(
  File "/Library/Frameworks/Python.framework/Versions/3.12/lib/python3.12/site-packages/neo4j/_sync/work/workspace.py", line 199, in _connect
    self._connection = self._pool.acquire(**acquire_kwargs_)
                       ^^^^^^^^^^^^^^^^^^^^^^^^^^^^^^^^^^^^^
  File "/Library/Frameworks/Python.framework/Versions/3.12/lib/python3.12/site-packages/neo4j/_sync/io/_pool.py", line 662, in acquire
    return self._acquire(
           ^^^^^^^^^^^^^^
  File "/Library/Frameworks/Python.framework/Versions/3.12/lib/python3.12/site-packages/neo4j/_sync/io/_pool.py", line 408, in _acquire
    return connection_creator()
           ^^^^^^^^^^^^^^^^^^^^
  File "/Library/Frameworks/Python.framework/Versions/3.12/lib/python3.12/site-packages/neo4j/_sync/io/_pool.py", line 230, in connection_creator
    connection = self.opener(
                 ^^^^^^^^^^^^
  File "/Library/Frameworks/Python.framework/Versions/3.12/lib/python3.12/site-packages/neo4j/_sync/io/_pool.py", line 624, in opener
    return Bolt.open(
           ^^^^^^^^^^
  File "/Library/Frameworks/Python.framework/Versions/3.12/lib/python3.12/site-packages/neo4j/_sync/io/_bolt.py", line 369, in open
    s, protocol_version, handshake, data = BoltSocket.connect(
                                           ^^^^^^^^^^^^^^^^^^^
  File "/Library/Frameworks/Python.framework/Versions/3.12/lib/python3.12/site-packages/neo4j/_sync/io/_bolt_socket.py", line 376, in connect
    raise ServiceUnavailable(
neo4j.exceptions.ServiceUnavailable: Couldn't connect to localhost:7687 (resolved to ('[::1]:7687', '127.0.0.1:7687')):
Failed to establish connection to ResolvedIPv6Address(('::1', 7687, 0, 0)) (reason [Errno 61] Connection refused)
Failed to establish connection to ResolvedIPv4Address(('127.0.0.1', 7687)) (reason [Errno 61] Connection refused)
ERROR:    Exception in ASGI application
Traceback (most recent call last):
  File "/Library/Frameworks/Python.framework/Versions/3.12/lib/python3.12/site-packages/neo4j/_async_compat/network/_bolt_socket.py", line 409, in _connect_secure
    s.connect(resolved_address)
ConnectionRefusedError: [Errno 61] Connection refused

The above exception was the direct cause of the following exception:

Traceback (most recent call last):
  File "/Library/Frameworks/Python.framework/Versions/3.12/lib/python3.12/site-packages/neo4j/_sync/io/_bolt_socket.py", line 328, in connect
    s = cls._connect_secure(
        ^^^^^^^^^^^^^^^^^^^^
  File "/Library/Frameworks/Python.framework/Versions/3.12/lib/python3.12/site-packages/neo4j/_async_compat/network/_bolt_socket.py", line 426, in _connect_secure
    raise ServiceUnavailable(
neo4j.exceptions.ServiceUnavailable: Failed to establish connection to ResolvedIPv6Address(('::1', 7687, 0, 0)) (reason [Errno 61] Connection refused)

The above exception was the direct cause of the following exception:

Traceback (most recent call last):
  File "/Library/Frameworks/Python.framework/Versions/3.12/lib/python3.12/site-packages/uvicorn/protocols/http/h11_impl.py", line 407, in run_asgi
    result = await app(  # type: ignore[func-returns-value]
             ^^^^^^^^^^^^^^^^^^^^^^^^^^^^^^^^^^^^^^^^^^^^^^
  File "/Library/Frameworks/Python.framework/Versions/3.12/lib/python3.12/site-packages/uvicorn/middleware/proxy_headers.py", line 69, in __call__
    return await self.app(scope, receive, send)
           ^^^^^^^^^^^^^^^^^^^^^^^^^^^^^^^^^^^^
  File "/Library/Frameworks/Python.framework/Versions/3.12/lib/python3.12/site-packages/fastapi/applications.py", line 1054, in __call__
    await super().__call__(scope, receive, send)
  File "/Library/Frameworks/Python.framework/Versions/3.12/lib/python3.12/site-packages/starlette/applications.py", line 123, in __call__
    await self.middleware_stack(scope, receive, send)
  File "/Library/Frameworks/Python.framework/Versions/3.12/lib/python3.12/site-packages/starlette/middleware/errors.py", line 186, in __call__
    raise exc
  File "/Library/Frameworks/Python.framework/Versions/3.12/lib/python3.12/site-packages/starlette/middleware/errors.py", line 164, in __call__
    await self.app(scope, receive, _send)
  File "/Library/Frameworks/Python.framework/Versions/3.12/lib/python3.12/site-packages/starlette/middleware/exceptions.py", line 65, in __call__
    await wrap_app_handling_exceptions(self.app, conn)(scope, receive, send)
  File "/Library/Frameworks/Python.framework/Versions/3.12/lib/python3.12/site-packages/starlette/_exception_handler.py", line 64, in wrapped_app
    raise exc
  File "/Library/Frameworks/Python.framework/Versions/3.12/lib/python3.12/site-packages/starlette/_exception_handler.py", line 53, in wrapped_app
    await app(scope, receive, sender)
  File "/Library/Frameworks/Python.framework/Versions/3.12/lib/python3.12/site-packages/starlette/routing.py", line 756, in __call__
    await self.middleware_stack(scope, receive, send)
  File "/Library/Frameworks/Python.framework/Versions/3.12/lib/python3.12/site-packages/starlette/routing.py", line 776, in app
    await route.handle(scope, receive, send)
  File "/Library/Frameworks/Python.framework/Versions/3.12/lib/python3.12/site-packages/starlette/routing.py", line 297, in handle
    await self.app(scope, receive, send)
  File "/Library/Frameworks/Python.framework/Versions/3.12/lib/python3.12/site-packages/starlette/routing.py", line 77, in app
    await wrap_app_handling_exceptions(app, request)(scope, receive, send)
  File "/Library/Frameworks/Python.framework/Versions/3.12/lib/python3.12/site-packages/starlette/_exception_handler.py", line 64, in wrapped_app
    raise exc
  File "/Library/Frameworks/Python.framework/Versions/3.12/lib/python3.12/site-packages/starlette/_exception_handler.py", line 53, in wrapped_app
    await app(scope, receive, sender)
  File "/Library/Frameworks/Python.framework/Versions/3.12/lib/python3.12/site-packages/starlette/routing.py", line 72, in app
    response = await func(request)
               ^^^^^^^^^^^^^^^^^^^
  File "/Library/Frameworks/Python.framework/Versions/3.12/lib/python3.12/site-packages/fastapi/routing.py", line 278, in app
    raw_response = await run_endpoint_function(
                   ^^^^^^^^^^^^^^^^^^^^^^^^^^^^
  File "/Library/Frameworks/Python.framework/Versions/3.12/lib/python3.12/site-packages/fastapi/routing.py", line 191, in run_endpoint_function
    return await dependant.call(**values)
           ^^^^^^^^^^^^^^^^^^^^^^^^^^^^^^
  File "/Users/ryan/src/msec/atgx/azure-tenant-grapher/src/visualization/server.py", line 108, in api_graph
    data = visualizer.extract_graph_data(link_to_hierarchy=True)
           ^^^^^^^^^^^^^^^^^^^^^^^^^^^^^^^^^^^^^^^^^^^^^^^^^^^^^
  File "/Users/ryan/src/msec/atgx/azure-tenant-grapher/src/graph_visualizer.py", line 200, in extract_graph_data
    self.connect()
  File "/Users/ryan/src/msec/atgx/azure-tenant-grapher/src/graph_visualizer.py", line 65, in connect
    session.run("RETURN 1")
  File "/Library/Frameworks/Python.framework/Versions/3.12/lib/python3.12/site-packages/neo4j/_sync/work/session.py", line 313, in run
    self._connect(self._config.default_access_mode)
  File "/Library/Frameworks/Python.framework/Versions/3.12/lib/python3.12/site-packages/neo4j/_sync/work/session.py", line 136, in _connect
    super()._connect(
  File "/Library/Frameworks/Python.framework/Versions/3.12/lib/python3.12/site-packages/neo4j/_sync/work/workspace.py", line 199, in _connect
    self._connection = self._pool.acquire(**acquire_kwargs_)
                       ^^^^^^^^^^^^^^^^^^^^^^^^^^^^^^^^^^^^^
  File "/Library/Frameworks/Python.framework/Versions/3.12/lib/python3.12/site-packages/neo4j/_sync/io/_pool.py", line 662, in acquire
    return self._acquire(
           ^^^^^^^^^^^^^^
  File "/Library/Frameworks/Python.framework/Versions/3.12/lib/python3.12/site-packages/neo4j/_sync/io/_pool.py", line 408, in _acquire
    return connection_creator()
           ^^^^^^^^^^^^^^^^^^^^
  File "/Library/Frameworks/Python.framework/Versions/3.12/lib/python3.12/site-packages/neo4j/_sync/io/_pool.py", line 230, in connection_creator
    connection = self.opener(
                 ^^^^^^^^^^^^
  File "/Library/Frameworks/Python.framework/Versions/3.12/lib/python3.12/site-packages/neo4j/_sync/io/_pool.py", line 624, in opener
    return Bolt.open(
           ^^^^^^^^^^
  File "/Library/Frameworks/Python.framework/Versions/3.12/lib/python3.12/site-packages/neo4j/_sync/io/_bolt.py", line 369, in open
    s, protocol_version, handshake, data = BoltSocket.connect(
                                           ^^^^^^^^^^^^^^^^^^^
  File "/Library/Frameworks/Python.framework/Versions/3.12/lib/python3.12/site-packages/neo4j/_sync/io/_bolt_socket.py", line 376, in connect
    raise ServiceUnavailable(
neo4j.exceptions.ServiceUnavailable: Couldn't connect to localhost:7687 (resolved to ('[::1]:7687', '127.0.0.1:7687')):
Failed to establish connection to ResolvedIPv6Address(('::1', 7687, 0, 0)) (reason [Errno 61] Connection refused)
Failed to establish connection to ResolvedIPv4Address(('127.0.0.1', 7687)) (reason [Errno 61] Connection refused)
Failed to connect to Neo4j: Couldn't connect to localhost:7687 (resolved to ('[::1]:7687', '127.0.0.1:7687')):
Failed to establish connection to ResolvedIPv6Address(('::1', 7687, 0, 0)) (reason [Errno 61] Connection refused)
Failed to establish connection to ResolvedIPv4Address(('127.0.0.1', 7687)) (reason [Errno 61] Connection refused)
Traceback (most recent call last):
  File "/Library/Frameworks/Python.framework/Versions/3.12/lib/python3.12/site-packages/neo4j/_async_compat/network/_bolt_socket.py", line 409, in _connect_secure
    s.connect(resolved_address)
ConnectionRefusedError: [Errno 61] Connection refused

The above exception was the direct cause of the following exception:

Traceback (most recent call last):
  File "/Library/Frameworks/Python.framework/Versions/3.12/lib/python3.12/site-packages/neo4j/_sync/io/_bolt_socket.py", line 328, in connect
    s = cls._connect_secure(
        ^^^^^^^^^^^^^^^^^^^^
  File "/Library/Frameworks/Python.framework/Versions/3.12/lib/python3.12/site-packages/neo4j/_async_compat/network/_bolt_socket.py", line 426, in _connect_secure
    raise ServiceUnavailable(
neo4j.exceptions.ServiceUnavailable: Failed to establish connection to ResolvedIPv6Address(('::1', 7687, 0, 0)) (reason [Errno 61] Connection refused)

The above exception was the direct cause of the following exception:

Traceback (most recent call last):
  File "/Users/ryan/src/msec/atgx/azure-tenant-grapher/src/graph_visualizer.py", line 65, in connect
    session.run("RETURN 1")
  File "/Library/Frameworks/Python.framework/Versions/3.12/lib/python3.12/site-packages/neo4j/_sync/work/session.py", line 313, in run
    self._connect(self._config.default_access_mode)
  File "/Library/Frameworks/Python.framework/Versions/3.12/lib/python3.12/site-packages/neo4j/_sync/work/session.py", line 136, in _connect
    super()._connect(
  File "/Library/Frameworks/Python.framework/Versions/3.12/lib/python3.12/site-packages/neo4j/_sync/work/workspace.py", line 199, in _connect
    self._connection = self._pool.acquire(**acquire_kwargs_)
                       ^^^^^^^^^^^^^^^^^^^^^^^^^^^^^^^^^^^^^
  File "/Library/Frameworks/Python.framework/Versions/3.12/lib/python3.12/site-packages/neo4j/_sync/io/_pool.py", line 662, in acquire
    return self._acquire(
           ^^^^^^^^^^^^^^
  File "/Library/Frameworks/Python.framework/Versions/3.12/lib/python3.12/site-packages/neo4j/_sync/io/_pool.py", line 408, in _acquire
    return connection_creator()
           ^^^^^^^^^^^^^^^^^^^^
  File "/Library/Frameworks/Python.framework/Versions/3.12/lib/python3.12/site-packages/neo4j/_sync/io/_pool.py", line 230, in connection_creator
    connection = self.opener(
                 ^^^^^^^^^^^^
  File "/Library/Frameworks/Python.framework/Versions/3.12/lib/python3.12/site-packages/neo4j/_sync/io/_pool.py", line 624, in opener
    return Bolt.open(
           ^^^^^^^^^^
  File "/Library/Frameworks/Python.framework/Versions/3.12/lib/python3.12/site-packages/neo4j/_sync/io/_bolt.py", line 369, in open
    s, protocol_version, handshake, data = BoltSocket.connect(
                                           ^^^^^^^^^^^^^^^^^^^
  File "/Library/Frameworks/Python.framework/Versions/3.12/lib/python3.12/site-packages/neo4j/_sync/io/_bolt_socket.py", line 376, in connect
    raise ServiceUnavailable(
neo4j.exceptions.ServiceUnavailable: Couldn't connect to localhost:7687 (resolved to ('[::1]:7687', '127.0.0.1:7687')):
Failed to establish connection to ResolvedIPv6Address(('::1', 7687, 0, 0)) (reason [Errno 61] Connection refused)
Failed to establish connection to ResolvedIPv4Address(('127.0.0.1', 7687)) (reason [Errno 61] Connection refused)
ERROR:    Exception in ASGI application
Traceback (most recent call last):
  File "/Library/Frameworks/Python.framework/Versions/3.12/lib/python3.12/site-packages/neo4j/_async_compat/network/_bolt_socket.py", line 409, in _connect_secure
    s.connect(resolved_address)
ConnectionRefusedError: [Errno 61] Connection refused

The above exception was the direct cause of the following exception:

Traceback (most recent call last):
  File "/Library/Frameworks/Python.framework/Versions/3.12/lib/python3.12/site-packages/neo4j/_sync/io/_bolt_socket.py", line 328, in connect
    s = cls._connect_secure(
        ^^^^^^^^^^^^^^^^^^^^
  File "/Library/Frameworks/Python.framework/Versions/3.12/lib/python3.12/site-packages/neo4j/_async_compat/network/_bolt_socket.py", line 426, in _connect_secure
    raise ServiceUnavailable(
neo4j.exceptions.ServiceUnavailable: Failed to establish connection to ResolvedIPv6Address(('::1', 7687, 0, 0)) (reason [Errno 61] Connection refused)

The above exception was the direct cause of the following exception:

Traceback (most recent call last):
  File "/Library/Frameworks/Python.framework/Versions/3.12/lib/python3.12/site-packages/uvicorn/protocols/http/h11_impl.py", line 407, in run_asgi
    result = await app(  # type: ignore[func-returns-value]
             ^^^^^^^^^^^^^^^^^^^^^^^^^^^^^^^^^^^^^^^^^^^^^^
  File "/Library/Frameworks/Python.framework/Versions/3.12/lib/python3.12/site-packages/uvicorn/middleware/proxy_headers.py", line 69, in __call__
    return await self.app(scope, receive, send)
           ^^^^^^^^^^^^^^^^^^^^^^^^^^^^^^^^^^^^
  File "/Library/Frameworks/Python.framework/Versions/3.12/lib/python3.12/site-packages/fastapi/applications.py", line 1054, in __call__
    await super().__call__(scope, receive, send)
  File "/Library/Frameworks/Python.framework/Versions/3.12/lib/python3.12/site-packages/starlette/applications.py", line 123, in __call__
    await self.middleware_stack(scope, receive, send)
  File "/Library/Frameworks/Python.framework/Versions/3.12/lib/python3.12/site-packages/starlette/middleware/errors.py", line 186, in __call__
    raise exc
  File "/Library/Frameworks/Python.framework/Versions/3.12/lib/python3.12/site-packages/starlette/middleware/errors.py", line 164, in __call__
    await self.app(scope, receive, _send)
  File "/Library/Frameworks/Python.framework/Versions/3.12/lib/python3.12/site-packages/starlette/middleware/exceptions.py", line 65, in __call__
    await wrap_app_handling_exceptions(self.app, conn)(scope, receive, send)
  File "/Library/Frameworks/Python.framework/Versions/3.12/lib/python3.12/site-packages/starlette/_exception_handler.py", line 64, in wrapped_app
    raise exc
  File "/Library/Frameworks/Python.framework/Versions/3.12/lib/python3.12/site-packages/starlette/_exception_handler.py", line 53, in wrapped_app
    await app(scope, receive, sender)
  File "/Library/Frameworks/Python.framework/Versions/3.12/lib/python3.12/site-packages/starlette/routing.py", line 756, in __call__
    await self.middleware_stack(scope, receive, send)
  File "/Library/Frameworks/Python.framework/Versions/3.12/lib/python3.12/site-packages/starlette/routing.py", line 776, in app
    await route.handle(scope, receive, send)
  File "/Library/Frameworks/Python.framework/Versions/3.12/lib/python3.12/site-packages/starlette/routing.py", line 297, in handle
    await self.app(scope, receive, send)
  File "/Library/Frameworks/Python.framework/Versions/3.12/lib/python3.12/site-packages/starlette/routing.py", line 77, in app
    await wrap_app_handling_exceptions(app, request)(scope, receive, send)
  File "/Library/Frameworks/Python.framework/Versions/3.12/lib/python3.12/site-packages/starlette/_exception_handler.py", line 64, in wrapped_app
    raise exc
  File "/Library/Frameworks/Python.framework/Versions/3.12/lib/python3.12/site-packages/starlette/_exception_handler.py", line 53, in wrapped_app
    await app(scope, receive, sender)
  File "/Library/Frameworks/Python.framework/Versions/3.12/lib/python3.12/site-packages/starlette/routing.py", line 72, in app
    response = await func(request)
               ^^^^^^^^^^^^^^^^^^^
  File "/Library/Frameworks/Python.framework/Versions/3.12/lib/python3.12/site-packages/fastapi/routing.py", line 278, in app
    raw_response = await run_endpoint_function(
                   ^^^^^^^^^^^^^^^^^^^^^^^^^^^^
  File "/Library/Frameworks/Python.framework/Versions/3.12/lib/python3.12/site-packages/fastapi/routing.py", line 191, in run_endpoint_function
    return await dependant.call(**values)
           ^^^^^^^^^^^^^^^^^^^^^^^^^^^^^^
  File "/Users/ryan/src/msec/atgx/azure-tenant-grapher/src/visualization/server.py", line 108, in api_graph
    data = visualizer.extract_graph_data(link_to_hierarchy=True)
           ^^^^^^^^^^^^^^^^^^^^^^^^^^^^^^^^^^^^^^^^^^^^^^^^^^^^^
  File "/Users/ryan/src/msec/atgx/azure-tenant-grapher/src/graph_visualizer.py", line 200, in extract_graph_data
    self.connect()
  File "/Users/ryan/src/msec/atgx/azure-tenant-grapher/src/graph_visualizer.py", line 65, in connect
    session.run("RETURN 1")
  File "/Library/Frameworks/Python.framework/Versions/3.12/lib/python3.12/site-packages/neo4j/_sync/work/session.py", line 313, in run
    self._connect(self._config.default_access_mode)
  File "/Library/Frameworks/Python.framework/Versions/3.12/lib/python3.12/site-packages/neo4j/_sync/work/session.py", line 136, in _connect
    super()._connect(
  File "/Library/Frameworks/Python.framework/Versions/3.12/lib/python3.12/site-packages/neo4j/_sync/work/workspace.py", line 199, in _connect
    self._connection = self._pool.acquire(**acquire_kwargs_)
                       ^^^^^^^^^^^^^^^^^^^^^^^^^^^^^^^^^^^^^
  File "/Library/Frameworks/Python.framework/Versions/3.12/lib/python3.12/site-packages/neo4j/_sync/io/_pool.py", line 662, in acquire
    return self._acquire(
           ^^^^^^^^^^^^^^
  File "/Library/Frameworks/Python.framework/Versions/3.12/lib/python3.12/site-packages/neo4j/_sync/io/_pool.py", line 408, in _acquire
    return connection_creator()
           ^^^^^^^^^^^^^^^^^^^^
  File "/Library/Frameworks/Python.framework/Versions/3.12/lib/python3.12/site-packages/neo4j/_sync/io/_pool.py", line 230, in connection_creator
    connection = self.opener(
                 ^^^^^^^^^^^^
  File "/Library/Frameworks/Python.framework/Versions/3.12/lib/python3.12/site-packages/neo4j/_sync/io/_pool.py", line 624, in opener
    return Bolt.open(
           ^^^^^^^^^^
  File "/Library/Frameworks/Python.framework/Versions/3.12/lib/python3.12/site-packages/neo4j/_sync/io/_bolt.py", line 369, in open
    s, protocol_version, handshake, data = BoltSocket.connect(
                                           ^^^^^^^^^^^^^^^^^^^
  File "/Library/Frameworks/Python.framework/Versions/3.12/lib/python3.12/site-packages/neo4j/_sync/io/_bolt_socket.py", line 376, in connect
    raise ServiceUnavailable(
neo4j.exceptions.ServiceUnavailable: Couldn't connect to localhost:7687 (resolved to ('[::1]:7687', '127.0.0.1:7687')):
Failed to establish connection to ResolvedIPv6Address(('::1', 7687, 0, 0)) (reason [Errno 61] Connection refused)
Failed to establish connection to ResolvedIPv4Address(('127.0.0.1', 7687)) (reason [Errno 61] Connection refused)
